Workbook

Sheet 测试记录
A2: 原型用户测试逐题记录
A4: 真实用户测试结果
A6: 用户编号 | B6: 测试日期 | C6: 测试条件 | D6: 题号 | E6: 候选事实 | F6: 用户选择 | G6: 是否正确 | H6: 完成时间（秒） | I6: 查看路径 | J6: 误解评分 | K6: 犹豫/回看 | L6: 用户原话 | M6: 观察备注 | N6: 严重度
A7: U01 | B7: 46298 | C7: A 仅候选 | D7: 正式01 | E7: =VLOOKUP(D7,题目索引!$A$6:$H$23,2,FALSE) -> ConceptNet—属于—常识知识图谱 | F7: 接受 | G7: =IF(F7="","",IF(F7=VLOOKUP(D7,题目索引!$A$6:$H$23,6,FALSE),"正确","错误")) -> 正确 | H7: 33 | I7: 否 | J7: 否 | K7: 否 | M7: 模拟预估：操作顺利。 | N7: 无
A8: U01 | B8: 46298 | C8: A 仅候选 | D8: 正式02 | E8: =VLOOKUP(D8,题目索引!$A$6:$H$23,2,FALSE) -> NELL—来源于—网页信息抽取 | F8: 接受 | G8: =IF(F8="","",IF(F8=VLOOKUP(D8,题目索引!$A$6:$H$23,6,FALSE),"正确","错误")) -> 正确 | H8: 33 | I8: 否 | J8: 否 | K8: 否 | M8: 模拟预估：操作顺利。 | N8: 无
A9: U01 | B9: 46298 | C9: A 仅候选 | D9: 正式03 | E9: =VLOOKUP(D9,题目索引!$A$6:$H$23,2,FALSE) -> BERT—开发机构—Google | F9: 接受 | G9: =IF(F9="","",IF(F9=VLOOKUP(D9,题目索引!$A$6:$H$23,6,FALSE),"正确","错误")) -> 正确 | H9: 33 | I9: 否 | J9: 否 | K9: 否 | M9: 模拟预估：操作顺利。 | N9: 无
A10: U01 | B10: 46298 | C10: A 仅候选 | D10: 正式04 | E10: =VLOOKUP(D10,题目索引!$A$6:$H$23,2,FALSE) -> CN15K—来源于—ConceptNet | F10: 暂缓 | G10: =IF(F10="","",IF(F10=VLOOKUP(D10,题目索引!$A$6:$H$23,6,FALSE),"正确","错误")) -> 错误 | H10: 38 | I10: 否 | J10: 否 | K10: 是 | L10: 信息不够，我先暂缓。 | M10: 模拟预估：证据不足或关系含义判断出现偏差。 | N10: P2 一般
A11: U01 | B11: 46298 | C11: A 仅候选 | D11: 正式05 | E11: =VLOOKUP(D11,题目索引!$A$6:$H$23,2,FALSE) -> NL27K—来源于—NELL | F11: 接受 | G11: =IF(F11="","",IF(F11=VLOOKUP(D11,题目索引!$A$6:$H$23,6,FALSE),"正确","错误")) -> 正确 | H11: 38 | I11: 否 | J11: 否 | K11: 否 | M11: 模拟预估：操作顺利。 | N11: 无
A12: U01 | B12: 46298 | C12: A 仅候选 | D12: 正式06 | E12: =VLOOKUP(D12,题目索引!$A$6:$H$23,2,FALSE) -> 知识图谱补全—相关任务—链接预测 | F12: 接受 | G12: =IF(F12="","",IF(F12=VLOOKUP(D12,题目索引!$A$6:$H$23,6,FALSE),"正确","错误")) -> 正确 | H12: 38 | I12: 否 | J12: 否 | K12: 否 | M12: 模拟预估：操作顺利。 | N12: 无
A13: U01 | B13: 46298 | C13: A 仅候选 | D13: 正式07 | E13: =VLOOKUP(D13,题目索引!$A$6:$H$23,2,FALSE) -> CN15K—来源于—NELL | F13: 暂缓 | G13: =IF(F13="","",IF(F13=VLOOKUP(D13,题目索引!$A$6:$H$23,6,FALSE),"正确","错误")) -> 错误 | H13: 42 | I13: 否 | J13: 否 | K13: 是 | M13: 模拟预估：证据不足或关系含义判断出现偏差。 | N13: P2 一般
A14: U01 | B14: 46298 | C14: A 仅候选 | D14: 正式08 | E14: =VLOOKUP(D14,题目索引!$A$6:$H$23,2,FALSE) -> NL27K—来源于—ConceptNet | F14: 驳回 | G14: =IF(F14="","",IF(F14=VLOOKUP(D14,题目索引!$A$6:$H$23,6,FALSE),"正确","错误")) -> 正确 | H14: 42 | I14: 否 | J14: 否 | K14: 是 | M14: 模拟预估：操作顺利。 | N14: 无
A15: U01 | B15: 46298 | C15: A 仅候选 | D15: 正式09 | E15: =VLOOKUP(D15,题目索引!$A$6:$H$23,2,FALSE) -> BERT—开发机构—OpenAI | F15: 驳回 | G15: =IF(F15="","",IF(F15=VLOOKUP(D15,题目索引!$A$6:$H$23,6,FALSE),"正确","错误")) -> 正确 | H15: 42 | I15: 否 | J15: 否 | K15: 是 | M15: 模拟预估：操作顺利。 | N15: 无
A16: U01 | B16: 46298 | C16: A 仅候选 | D16: 正式10 | E16: =VLOOKUP(D16,题目索引!$A$6:$H$23,2,FALSE) -> 银川—位于—甘肃 | F16: 暂缓 | G16: =IF(F16="","",IF(F16=VLOOKUP(D16,题目索引!$A$6:$H$23,6,FALSE),"正确","错误")) -> 错误 | H16: 42 | I16: 否 | J16: 否 | K16: 是 | M16: 模拟预估：证据不足或关系含义判断出现偏差。 | N16: P2 一般
A17: U01 | B17: 46298 | C17: A 仅候选 | D17: 正式11 | E17: =VLOOKUP(D17,题目索引!$A$6:$H$23,2,FALSE) -> ConceptNet—属于—金融风控数据集 | F17: 驳回 | G17: =IF(F17="","",IF(F17=VLOOKUP(D17,题目索引!$A$6:$H$23,6,FALSE),"正确","错误")) -> 正确 | H17: 42 | I17: 否 | J17: 否 | K17: 否 | M17: 模拟预估：操作顺利。 | N17: 无
A18: U01 | B18: 46298 | C18: A 仅候选 | D18: 正式12 | E18: =VLOOKUP(D18,题目索引!$A$6:$H$23,2,FALSE) -> UBERT-RM—用于—图像分割 | F18: 驳回 | G18: =IF(F18="","",IF(F18=VLOOKUP(D18,题目索引!$A$6:$H$23,6,FALSE),"正确","错误")) -> 正确 | H18: 42 | I18: 否 | J18: 否 | K18: 否 | M18: 模拟预估：操作顺利。 | N18: 无
A19: U01 | B19: 46298 | C19: A 仅候选 | D19: 正式13 | E19: =VLOOKUP(D19,题目索引!$A$6:$H$23,2,FALSE) -> 宁夏大学—位于—银川 | F19: 暂缓 | G19: =IF(F19="","",IF(F19=VLOOKUP(D19,题目索引!$A$6:$H$23,6,FALSE),"正确","错误")) -> 错误 | H19: 39 | I19: 否 | J19: 否 | K19: 是 | M19: 模拟预估：证据不足或关系含义判断出现偏差。 | N19: P2 一般
A20: U01 | B20: 46298 | C20: A 仅候选 | D20: 正式14 | E20: =VLOOKUP(D20,题目索引!$A$6:$H$23,2,FALSE) -> CN15K—包含关系数量—36 | F20: 接受 | G20: =IF(F20="","",IF(F20=VLOOKUP(D20,题目索引!$A$6:$H$23,6,FALSE),"正确","错误")) -> 正确 | H20: 39 | I20: 否 | J20: 否 | K20: 否 | M20: 模拟预估：操作顺利。 | N20: 无
A21: U01 | B21: 46298 | C21: A 仅候选 | D21: 正式15 | E21: =VLOOKUP(D21,题目索引!$A$6:$H$23,2,FALSE) -> NL27K—包含实体数量—15000 | F21: 驳回 | G21: =IF(F21="","",IF(F21=VLOOKUP(D21,题目索引!$A$6:$H$23,6,FALSE),"正确","错误")) -> 正确 | H21: 39 | I21: 否 | J21: 否 | K21: 否 | M21: 模拟预估：操作顺利。 | N21: 无
A22: U01 | B22: 46298 | C22: A 仅候选 | D22: 正式16 | E22: =VLOOKUP(D22,题目索引!$A$6:$H$23,2,FALSE) -> UBERT-RM—适用于—医疗知识图谱生产系统 | F22: 暂缓 | G22: =IF(F22="","",IF(F22=VLOOKUP(D22,题目索引!$A$6:$H$23,6,FALSE),"正确","错误")) -> 正确 | H22: 46 | I22: 否 | J22: 否 | K22: 是 | M22: 模拟预估：操作顺利。 | N22: 无
... A30: U02 | B30: 46298 | C30: B 候选+评分 | D30: 正式06 | E30: =VLOOKUP(D30,题目索引!$A$6:$H$23,2,FALSE) -> 知识图谱补全—相关任务—链接预测 | F30: 接受 | G30: =IF(F30="","",IF(F30=VLOOKUP(D30,题目索引!$A$6:$H$23,6,FALSE),"正确","错误")) -> 正确 | H30: 34 | I30: 否 | J30: 否 | K30: 否 | M30: 模拟预估：操作顺利。 | N30: 无
A31: U02 | B31: 46298 | C31: B 候选+评分 | D31: 正式07 | E31: =VLOOKUP(D31,题目索引!$A$6:$H$23,2,FALSE) -> CN15K—来源于—NELL | F31: 接受 | G31: =IF(F31="","",IF(F31=VLOOKUP(D31,题目索引!$A$6:$H$23,6,FALSE),"正确","错误")) -> 错误 | H31: 38 | I31: 否 | J31: 是 | K31: 是 | L31: 分数这么高，应该可以接受。 | M31: 模拟预估：将模型评分或相关路径当成事实成立的强证据。 | N31: P1 严重
A32: U02 | B32: 46298 | C32: B 候选+评分 | D32: 正式08 | E32: =VLOOKUP(D32,题目索引!$A$6:$H$23,2,FALSE) -> NL27K—来源于—ConceptNet | F32: 驳回 | G32: =IF(F32="","",IF(F32=VLOOKUP(D32,题目索引!$A$6:$H$23,6,FALSE),"正确","错误")) -> 正确 | H32: 38 | I32: 否 | J32: 否 | K32: 是 | M32: 模拟预估：操作顺利。 | N32: 无
A33: U02 | B33: 46298 | C33: B 候选+评分 | D33: 正式09 | E33: =VLOOKUP(D33,题目索引!$A$6:$H$23,2,FALSE) -> BERT—开发机构—OpenAI | F33: 接受 | G33: =IF(F33="","",IF(F33=VLOOKUP(D33,题目索引!$A$6:$H$23,6,FALSE),"正确","错误")) -> 错误 | H33: 38 | I33: 否 | J33: 是 | K33: 是 | L33: 0.863看起来很可信。 | M33: 模拟预估：将模型评分或相关路径当成事实成立的强证据。 | N33: P1 严重
A34: U02 | B34: 46298 | C34: B 候选+评分 | D34: 正式10 | E34: =VLOOKUP(D34,题目索引!$A$6:$H$23,2,FALSE) -> 银川—位于—甘肃 | F34: 驳回 | G34: =IF(F34="","",IF(F34=VLOOKUP(D34,题目索引!$A$6:$H$23,6,FALSE),"正确","错误")) -> 正确 | H34: 38 | I34: 否 | J34: 是 | K34: 否 | M34: 模拟预估：将模型评分或相关路径当成事实成立的强证据。 | N34: P1 严重
A35: U02 | B35: 46298 | C35: B 候选+评分 | D35: 正式11 | E35: =VLOOKUP(D35,题目索引!$A$6:$H$23,2,FALSE) -> ConceptNet—属于—金融风控数据集 | F35: 驳回 | G35: =IF(F35="","",IF(F35=VLOOKUP(D35,题目索引!$A$6:$H$23,6,FALSE),"正确","错误")) -> 正确 | H35: 38 | I35: 否 | J35: 否 | K35: 否 | M35: 模拟预估：操作顺利。 | N35: 无
A36: U02 | B36: 46298 | C36: B 候选+评分 | D36: 正式12 | E36: =VLOOKUP(D36,题目索引!$A$6:$H$23,2,FALSE) -> UBERT-RM—用于—图像分割 | F36: 驳回 | G36: =IF(F36="","",IF(F36=VLOOKUP(D36,题目索引!$A$6:$H$23,6,FALSE),"正确","错误")) -> 正确 | H36: 38 | I36: 否 | J36: 否 | K36: 否 | M36: 模拟预估：操作顺利。 | N36: 无
A37: U02 | B37: 46298 | C37: B 候选+评分 | D37: 正式13 | E37: =VLOOKUP(D37,题目索引!$A$6:$H$23,2,FALSE) -> 宁夏大学—位于—银川 | F37: 接受 | G37: =IF(F37="","",IF(F37=VLOOKUP(D37,题目索引!$A$6:$H$23,6,FALSE),"正确","错误")) -> 正确 | H37: 35 | I37: 否 | J37: 否 | K37: 否 | M37: 模拟预估：操作顺利。 | N37: 无
A38: U02 | B38: 46298 | C38: B 候选+评分 | D38: 正式14 | E38: =VLOOKUP(D38,题目索引!$A$6:$H$23,2,FALSE) -> CN15K—包含关系数量—36 | F38: 接受 | G38: =IF(F38="","",IF(F38=VLOOKUP(D38,题目索引!$A$6:$H$23,6,FALSE),"正确","错误")) -> 正确 | H38: 35 | I38: 否 | J38: 否 | K38: 否 | M38: 模拟预估：操作顺利。 | N38: 无
A39: U02 | B39: 46298 | C39: B 候选+评分 | D39: 正式15 | E39: =VLOOKUP(D39,题目索引!$A$6:$H$23,2,FALSE) -> NL27K—包含实体数量—15000 | F39: 驳回 | G39: =IF(F39="","",IF(F39=VLOOKUP(D39,题目索引!$A$6:$H$23,6,FALSE),"正确","错误")) -> 正确 | H39: 35 | I39: 否 | J39: 否 | K39: 否 | M39: 模拟预估：操作顺利。 | N39: 无
A40: U02 | B40: 46298 | C40: B 候选+评分 | D40: 正式16 | E40: =VLOOKUP(D40,题目索引!$A$6:$H$23,2,FALSE) -> UBERT-RM—适用于—医疗知识图谱生产系统 | F40: 接受 | G40: =IF(F40="","",IF(F40=VLOOKUP(D40,题目索引!$A$6:$H$23,6,FALSE),"正确","错误")) -> 错误 | H40: 42 | I40: 否 | J40: 是 | K40: 是 | M40: 模拟预估：将模型评分或相关路径当成事实成立的强证据。 | N40: P1 严重
A41: U02 | B41: 46298 | C41: B 候选+评分 | D41: 正式17 | E41: =VLOOKUP(D41,题目索引!$A$6:$H$23,2,FALSE) -> 路径跳数4—一定优于—路径跳数3 | F41: 暂缓 | G41: =IF(F41="","",IF(F41=VLOOKUP(D41,题目索引!$A$6:$H$23,6,FALSE),"正确","错误")) -> 正确 | H41: 42 | I41: 否 | J41: 否 | K41: 是 | M41: 模拟预估：操作顺利。 | N41: 无
A42: U02 | B42: 46298 | C42: B 候选+评分 | D42: 正式18 | E42: =VLOOKUP(D42,题目索引!$A$6:$H$23,2,FALSE) -> 子图跳数3—是所有场景的最佳配置 | F42: 接受 | G42: =IF(F42="","",IF(F42=VLOOKUP(D42,题目索引!$A$6:$H$23,6,FALSE),"正确","错误")) -> 错误 | H42: 42 | I42: 否 | J42: 是 | K42: 是 | M42: 模拟预估：将模型评分或相关路径当成事实成立的强证据。 | N42: P1 严重
A43: U03 | B43: 46298 | C43: C 候选+评分+路径 | D43: 正式01 | E43: =VLOOKUP(D43,题目索引!$A$6:$H$23,2,FALSE) -> ConceptNet—属于—常识知识图谱 | F43: 接受 | G43: =IF(F43="","",IF(F43=VLOOKUP(D43,题目索引!$A$6:$H$23,6,FALSE),"正确","错误")) -> 正确 | H43: 26 | I43: 是 | J43: 否 | K43: 否 | M43: 模拟预估：操作顺利。 | N43: 无
A44: U03 | B44: 46298 | C44: C 候选+评分+路径 | D44: 正式02 | E44: =VLOOKUP(D44,题目索引!$A$6:$H$23,2,FALSE) -> NELL—来源于—网页信息抽取 | F44: 接受 | G44: =IF(F44="","",IF(F44=VLOOKUP(D44,题目索引!$A$6:$H$23,6,FALSE),"正确","错误")) -> 正确 | H44: 26 | I44: 是 | J44: 否 | K44: 否 | M44: 模拟预估：操作顺利。 | N44: 无
A45: U03 | B45: 46298 | C45: C 候选+评分+路径 | D45: 正式03 | E45: =VLOOKUP(D45,题目索引!$A$6:$H$23,2,FALSE) -> BERT—开发机构—Google | F45: 接受 | G45: =IF(F45="","",IF(F45=VLOOKUP(D45,题目索引!$A$6:$H$23,6,FALSE),"正确","错误")) -> 正确 | H45: 26 | I45: 是 | J45: 否 | K45: 否 | M45: 模拟预估：操作顺利。 | N45: 无
... A48: U03 | B48: 46298 | C48: C 候选+评分+路径 | D48: 正式06 | E48: =VLOOKUP(D48,题目索引!$A$6:$H$23,2,FALSE) -> 知识图谱补全—相关任务—链接预测 | F48: 接受 | G48: =IF(F48="","",IF(F48=VLOOKUP(D48,题目索引!$A$6:$H$23,6,FALSE),"正确","错误")) -> 正确 | H48: 31 | I48: 是 | J48: 否 | K48: 否 | M48: 模拟预估：操作顺利。 | N48: 无
A49: U03 | B49: 46298 | C49: C 候选+评分+路径 | D49: 正式07 | E49: =VLOOKUP(D49,题目索引!$A$6:$H$23,2,FALSE) -> CN15K—来源于—NELL | F49: 接受 | G49: =IF(F49="","",IF(F49=VLOOKUP(D49,题目索引!$A$6:$H$23,6,FALSE),"正确","错误")) -> 错误 | H49: 35 | I49: 是 | J49: 是 | K49: 是 | L49: 两边都属于同一类，可能存在来源关系。 | M49: 模拟预估：将模型评分或相关路径当成事实成立的强证据。 | N49: P1 严重
A50: U03 | B50: 46298 | C50: C 候选+评分+路径 | D50: 正式08 | E50: =VLOOKUP(D50,题目索引!$A$6:$H$23,2,FALSE) -> NL27K—来源于—ConceptNet | F50: 驳回 | G50: =IF(F50="","",IF(F50=VLOOKUP(D50,题目索引!$A$6:$H$23,6,FALSE),"正确","错误")) -> 正确 | H50: 35 | I50: 是 | J50: 否 | K50: 是 | M50: 模拟预估：查看路径后识别出相关性不足以支持候选结论。 | N50: 无
A51: U03 | B51: 46298 | C51: C 候选+评分+路径 | D51: 正式09 | E51: =VLOOKUP(D51,题目索引!$A$6:$H$23,2,FALSE) -> BERT—开发机构—OpenAI | F51: 驳回 | G51: =IF(F51="","",IF(F51=VLOOKUP(D51,题目索引!$A$6:$H$23,6,FALSE),"正确","错误")) -> 正确 | H51: 35 | I51: 是 | J51: 否 | K51: 是 | M51: 模拟预估：查看路径后识别出相关性不足以支持候选结论。 | N51: 无
A52: U03 | B52: 46298 | C52: C 候选+评分+路径 | D52: 正式10 | E52: =VLOOKUP(D52,题目索引!$A$6:$H$23,2,FALSE) -> 银川—位于—甘肃 | F52: 驳回 | G52: =IF(F52="","",IF(F52=VLOOKUP(D52,题目索引!$A$6:$H$23,6,FALSE),"正确","错误")) -> 正确 | H52: 35 | I52: 是 | J52: 否 | K52: 否 | M52: 模拟预估：查看路径后识别出相关性不足以支持候选结论。 | N52: 无
...

Sheet 题目索引
A2: 正式测试题目索引与参考答案
A5: 题号 | B5: 候选事实 | C5: 模型评分 | D5: 路径证据 | E5: 题目类型 | F5: 参考答案 | G5: 判断依据 | H5: 测试目的
A6: 正式01 | B6: ConceptNet—属于—常识知识图谱 | C6: 0.891 | D6: ConceptNet—用于表示—常识知识（0.87） | E6: 高分正确 | F6: 接受 | G6: ConceptNet是常识知识图谱。 | H6: 高分且证据一致
A7: 正式02 | B7: NELL—来源于—网页信息抽取 | C7: 0.847 | D7: NELL—从网页持续抽取—结构化知识（0.82） | E7: 高分正确 | F7: 接受 | G7: NELL通过持续网页信息抽取构建知识。 | H7: 自然语言路径
A8: 正式03 | B8: BERT—开发机构—Google | C8: 0.756 | D8: BERT—由研究团队提出—Google（0.74） | E8: 中分正确 | F8: 接受 | G8: BERT由Google研究团队提出。 | H8: 中等评分
A9: 正式04 | B9: CN15K—来源于—ConceptNet | C9: 0.438 | D9: CN15K—由常识图谱构建—ConceptNet（0.81） | E9: 低分正确 | F9: 接受 | G9: CN15K来源于ConceptNet。 | H9: 低分偏见
A10: 正式05 | B10: NL27K—来源于—NELL | C10: 0.491 | D10: NL27K—数据来源—NELL（0.79） | E10: 低分正确 | F10: 接受 | G10: NL27K来源于NELL。 | H10: 低分偏见
A11: 正式06 | B11: 知识图谱补全—相关任务—链接预测 | C11: 0.526 | D11: 知识图谱补全—预测缺失实体—链接预测（0.71） | E11: 低分正确 | F11: 接受 | G11: 链接预测是知识图谱补全的典型任务。 | H11: 路径纠正低分怀疑
A12: 正式07 | B12: CN15K—来源于—NELL | C12: 0.918 | D12: CN15K和NELL均属于不确定知识图谱 | E12: 高分错误 | F12: 驳回 | G12: 同属一个领域不能证明来源关系；CN15K来源于ConceptNet。 | H12: 高分和误导路径
A13: 正式08 | B13: NL27K—来源于—ConceptNet | C13: 0.887 | D13: NL27K用于知识图谱实验；ConceptNet属于知识图谱 | E13: 高分错误 | F13: 驳回 | G13: 存在领域关联不能推出数据来源；NL27K来源于NELL。 | H13: 关联不等于来源
A14: 正式09 | B14: BERT—开发机构—OpenAI | C14: 0.863 | D14: BERT和OpenAI均与人工智能相关 | E14: 高分错误 | F14: 驳回 | G14: BERT由Google研究团队提出。 | H14: 抵抗高分误导
A15: 正式10 | B15: 银川—位于—甘肃 | C15: 0.821 | D15: 银川和甘肃均位于中国西北地区 | E15: 实体错误 | F15: 驳回 | G15: 同属西北地区不能推出银川位于甘肃；银川位于宁夏。 | H15: 路径结论强度不足
A16: 正式11 | B16: ConceptNet—属于—金融风控数据集 | C16: 0.734 | D16: ConceptNet和金融风控都与人工智能应用有关 | E16: 类别错误 | F16: 驳回 | G16: 共享应用领域不能证明类别归属。 | H16: 过度推理
A17: 正式12 | B17: UBERT-RM—用于—图像分割 | C17: 0.701 | D17: UBERT-RM和图像分割都使用神经网络 | E17: 关系错误 | F17: 驳回 | G17: 相似技术不代表相同用途；UBERT-RM用于不确定知识图谱补全。 | H17: 共享技术路径
... A23: 正式18 | B23: 子图跳数3—是所有场景的最佳配置 | C23: 0.836 | D23: NL27K偏向3跳；CN15K偏向2跳 | E23: 证据冲突 | F23: 暂缓 | G23: 不同数据集的最佳设置不同，不能确定统一配置。 | H23: 证据冲突

Sheet 使用说明
A2: 原型用户测试记录表 V1.0
A5: 用途 | B5: 记录6至8名目标用户完成18道正式题时的行为和结果。
A6: 填写方式 | B6: 每位用户使用U01、U02等匿名编号；每道题填写一行。
A7: 用户选择 | B7: 从接受、驳回、暂缓中选择。是否正确将自动计算。
A8: 完成时间 | B8: 填写从看到题目到提交判断所用的秒数。
A9: 行为记录 | B9: 记录是否查看路径、是否误解评分，以及有价值的用户原话。
A10: 重要边界 | B10: 评分和路径均为原型测试模拟信息，不是真实模型输出。
A11: 正式测试前 | B11: 先完成审题和1场内部预测试，再开始6至8名用户的正式测试。

Sheet 模拟结果摘要
A2: 原型用户测试模拟摘要
A4: 以下结果来自6名用户的预测记录验证。
A6: 指标 | B6: 模拟结果
A7: 用户数 | B7: 6
A8: 逐题记录数 | B8: 108
A9: 总体判断正确率 | B9: =COUNTIF(测试记录!$G$7:$G$114,"正确")/COUNTA(测试记录!$D$7:$D$114) -> 0.80555556
A10: 平均单题耗时（秒） | B10: =AVERAGE(测试记录!$H$7:$H$114) -> 35.333333
A12: 测试条件 | B12: 用户数 | C12: 记录数 | D12: 判断正确率 | E12: 平均耗时（秒）
A13: A 仅候选 | B13: 2 | C13: =COUNTIF(测试记录!$C$7:$C$114,A13) -> 36 | D13: =COUNTIFS(测试记录!$C$7:$C$114,A13,测试记录!$G$7:$G$114,"正确")/C13 -> 0.75 | E13: =AVERAGEIFS(测试记录!$H$7:$H$114,测试记录!$C$7:$C$114,A13) -> 40
A14: B 候选+评分 | B14: 2 | C14: =COUNTIF(测试记录!$C$7:$C$114,A14) -> 36 | D14: =COUNTIFS(测试记录!$C$7:$C$114,A14,测试记录!$G$7:$G$114,"正确")/C14 -> 0.80555556 | E14: =AVERAGEIFS(测试记录!$H$7:$H$114,测试记录!$C$7:$C$114,A14) -> 33
A15: C 候选+评分+路径 | B15: 2 | C15: =COUNTIF(测试记录!$C$7:$C$114,A15) -> 36 | D15: =COUNTIFS(测试记录!$C$7:$C$114,A15,测试记录!$G$7:$G$114,"正确")/C15 -> 0.86111111 | E15: =AVERAGEIFS(测试记录!$H$7:$H$114,测试记录!$C$7:$C$114,A15) -> 33
A16: 合计 | B16: 6 | C16: 108 | D16: =COUNTIF(测试记录!$G$7:$G$114,"正确")/C16 -> 0.80555556 | E16: =AVERAGE(测试记录!$H$7:$H$114) -> 35.333333
A18: 预判问题 | B18: 模拟表现
A19: 高分错误候选可能诱发盲从 | B19: B条件中部分用户直接接受高分错误候选。
A20: 路径有助于识别过度推理 | B20: C条件总体正确率高于B条件，但阅读路径增加部分耗时。
A21: 暂缓的使用边界不清晰 | B21: 面对配置结论和未验证应用场景时，部分用户仍选择直接接受。
A22: 无路径不等于候选错误 | B22: 模拟中仍有人因缺少路径而暂缓正确事实。
A24: 建议 | B24: 后续动作
A25: 测试前优化 | B25: 强化“评分不等于正确概率”，并解释路径只能作为辅助证据。
